DEBUG 2019-06-14 15:57:25,967: 	 Executing command: 'status'
DEBUG 2019-06-14 15:57:25,967: 	 Found CRAB cache file /afs/cern.ch/user/q/qihuang/.crab3
ERROR 2019-06-14 15:57:25,968: 	 Error: crab_TTJets-1 is not a valid CRAB project directory.
ERROR 2019-06-14 15:57:25,968: 	 Caught exception
Traceback (most recent call last):
  File "/cvmfs/cms.cern.ch/crab3/slc6_amd64_gcc493/cms/crabclient/3.3.1904/bin/crab", line 161, in <module>
    client()
  File "/cvmfs/cms.cern.ch/crab3/slc6_amd64_gcc493/cms/crabclient/3.3.1904/bin/crab", line 146, in __call__
    self.cmd = sub_cmd(self.logger, args[1:])
  File "/cvmfs/cms.cern.ch/crab3/slc6_amd64_gcc493/cms/crabclient/3.3.1904/lib/python2.7/site-packages/CRABClient/Commands/status.py", line 40, in __init__
    SubCommand.__init__(self, logger, cmdargs)
  File "/cvmfs/cms.cern.ch/crab3/slc6_amd64_gcc493/cms/crabclient/3.3.1904/lib/python2.7/site-packages/CRABClient/Commands/SubCommand.py", line 268, in __init__
    SubCommand.validateOptions(self)
  File "/cvmfs/cms.cern.ch/crab3/slc6_amd64_gcc493/cms/crabclient/3.3.1904/lib/python2.7/site-packages/CRABClient/Commands/SubCommand.py", line 586, in validateOptions
    raise ConfigurationException(msg)
ConfigurationException: [91mError[0m: crab_TTJets-1 is not a valid CRAB project directory.
DEBUG 2019-06-14 15:57:26,453: 	 Executing command: 'status'
DEBUG 2019-06-14 15:57:26,453: 	 Found CRAB cache file /afs/cern.ch/user/q/qihuang/.crab3
ERROR 2019-06-14 15:57:26,453: 	 Error: crab_TTJets-2 is not a valid CRAB project directory.
ERROR 2019-06-14 15:57:26,453: 	 Caught exception
Traceback (most recent call last):
  File "/cvmfs/cms.cern.ch/crab3/slc6_amd64_gcc493/cms/crabclient/3.3.1904/bin/crab", line 161, in <module>
    client()
  File "/cvmfs/cms.cern.ch/crab3/slc6_amd64_gcc493/cms/crabclient/3.3.1904/bin/crab", line 146, in __call__
    self.cmd = sub_cmd(self.logger, args[1:])
  File "/cvmfs/cms.cern.ch/crab3/slc6_amd64_gcc493/cms/crabclient/3.3.1904/lib/python2.7/site-packages/CRABClient/Commands/status.py", line 40, in __init__
    SubCommand.__init__(self, logger, cmdargs)
  File "/cvmfs/cms.cern.ch/crab3/slc6_amd64_gcc493/cms/crabclient/3.3.1904/lib/python2.7/site-packages/CRABClient/Commands/SubCommand.py", line 268, in __init__
    SubCommand.validateOptions(self)
  File "/cvmfs/cms.cern.ch/crab3/slc6_amd64_gcc493/cms/crabclient/3.3.1904/lib/python2.7/site-packages/CRABClient/Commands/SubCommand.py", line 586, in validateOptions
    raise ConfigurationException(msg)
ConfigurationException: [91mError[0m: crab_TTJets-2 is not a valid CRAB project directory.
DEBUG 2019-06-14 15:59:42,386: 	 Executing command: 'status'
DEBUG 2019-06-14 15:59:42,386: 	 Found CRAB cache file /afs/cern.ch/user/q/qihuang/.crab3
ERROR 2019-06-14 15:59:42,387: 	 Error: crab_WJets-1 is not a valid CRAB project directory.
ERROR 2019-06-14 15:59:42,387: 	 Caught exception
Traceback (most recent call last):
  File "/cvmfs/cms.cern.ch/crab3/slc6_amd64_gcc493/cms/crabclient/3.3.1904/bin/crab", line 161, in <module>
    client()
  File "/cvmfs/cms.cern.ch/crab3/slc6_amd64_gcc493/cms/crabclient/3.3.1904/bin/crab", line 146, in __call__
    self.cmd = sub_cmd(self.logger, args[1:])
  File "/cvmfs/cms.cern.ch/crab3/slc6_amd64_gcc493/cms/crabclient/3.3.1904/lib/python2.7/site-packages/CRABClient/Commands/status.py", line 40, in __init__
    SubCommand.__init__(self, logger, cmdargs)
  File "/cvmfs/cms.cern.ch/crab3/slc6_amd64_gcc493/cms/crabclient/3.3.1904/lib/python2.7/site-packages/CRABClient/Commands/SubCommand.py", line 268, in __init__
    SubCommand.validateOptions(self)
  File "/cvmfs/cms.cern.ch/crab3/slc6_amd64_gcc493/cms/crabclient/3.3.1904/lib/python2.7/site-packages/CRABClient/Commands/SubCommand.py", line 586, in validateOptions
    raise ConfigurationException(msg)
ConfigurationException: [91mError[0m: crab_WJets-1 is not a valid CRAB project directory.
DEBUG 2019-06-14 15:59:42,856: 	 Executing command: 'status'
DEBUG 2019-06-14 15:59:42,857: 	 Found CRAB cache file /afs/cern.ch/user/q/qihuang/.crab3
ERROR 2019-06-14 15:59:42,857: 	 Error: crab_WJets-2 is not a valid CRAB project directory.
ERROR 2019-06-14 15:59:42,857: 	 Caught exception
Traceback (most recent call last):
  File "/cvmfs/cms.cern.ch/crab3/slc6_amd64_gcc493/cms/crabclient/3.3.1904/bin/crab", line 161, in <module>
    client()
  File "/cvmfs/cms.cern.ch/crab3/slc6_amd64_gcc493/cms/crabclient/3.3.1904/bin/crab", line 146, in __call__
    self.cmd = sub_cmd(self.logger, args[1:])
  File "/cvmfs/cms.cern.ch/crab3/slc6_amd64_gcc493/cms/crabclient/3.3.1904/lib/python2.7/site-packages/CRABClient/Commands/status.py", line 40, in __init__
    SubCommand.__init__(self, logger, cmdargs)
  File "/cvmfs/cms.cern.ch/crab3/slc6_amd64_gcc493/cms/crabclient/3.3.1904/lib/python2.7/site-packages/CRABClient/Commands/SubCommand.py", line 268, in __init__
    SubCommand.validateOptions(self)
  File "/cvmfs/cms.cern.ch/crab3/slc6_amd64_gcc493/cms/crabclient/3.3.1904/lib/python2.7/site-packages/CRABClient/Commands/SubCommand.py", line 586, in validateOptions
    raise ConfigurationException(msg)
ConfigurationException: [91mError[0m: crab_WJets-2 is not a valid CRAB project directory.
DEBUG 2019-06-14 23:55:22,325: 	 Executing command: 'status'
DEBUG 2019-06-14 23:55:22,338: 	 Found CRAB cache file /afs/cern.ch/user/q/qihuang/.crab3
ERROR 2019-06-14 23:55:22,359: 	 Error: crab_TTJets-1 is not a valid CRAB project directory.
ERROR 2019-06-14 23:55:22,360: 	 Caught exception
Traceback (most recent call last):
  File "/cvmfs/cms.cern.ch/crab3/slc6_amd64_gcc493/cms/crabclient/3.3.1904/bin/crab", line 161, in <module>
    client()
  File "/cvmfs/cms.cern.ch/crab3/slc6_amd64_gcc493/cms/crabclient/3.3.1904/bin/crab", line 146, in __call__
    self.cmd = sub_cmd(self.logger, args[1:])
  File "/cvmfs/cms.cern.ch/crab3/slc6_amd64_gcc493/cms/crabclient/3.3.1904/lib/python2.7/site-packages/CRABClient/Commands/status.py", line 40, in __init__
    SubCommand.__init__(self, logger, cmdargs)
  File "/cvmfs/cms.cern.ch/crab3/slc6_amd64_gcc493/cms/crabclient/3.3.1904/lib/python2.7/site-packages/CRABClient/Commands/SubCommand.py", line 268, in __init__
    SubCommand.validateOptions(self)
  File "/cvmfs/cms.cern.ch/crab3/slc6_amd64_gcc493/cms/crabclient/3.3.1904/lib/python2.7/site-packages/CRABClient/Commands/SubCommand.py", line 586, in validateOptions
    raise ConfigurationException(msg)
ConfigurationException: [91mError[0m: crab_TTJets-1 is not a valid CRAB project directory.
DEBUG 2019-06-14 23:55:22,934: 	 Executing command: 'status'
DEBUG 2019-06-14 23:55:22,934: 	 Found CRAB cache file /afs/cern.ch/user/q/qihuang/.crab3
ERROR 2019-06-14 23:55:22,934: 	 Error: crab_TTJets-2 is not a valid CRAB project directory.
ERROR 2019-06-14 23:55:22,934: 	 Caught exception
Traceback (most recent call last):
  File "/cvmfs/cms.cern.ch/crab3/slc6_amd64_gcc493/cms/crabclient/3.3.1904/bin/crab", line 161, in <module>
    client()
  File "/cvmfs/cms.cern.ch/crab3/slc6_amd64_gcc493/cms/crabclient/3.3.1904/bin/crab", line 146, in __call__
    self.cmd = sub_cmd(self.logger, args[1:])
  File "/cvmfs/cms.cern.ch/crab3/slc6_amd64_gcc493/cms/crabclient/3.3.1904/lib/python2.7/site-packages/CRABClient/Commands/status.py", line 40, in __init__
    SubCommand.__init__(self, logger, cmdargs)
  File "/cvmfs/cms.cern.ch/crab3/slc6_amd64_gcc493/cms/crabclient/3.3.1904/lib/python2.7/site-packages/CRABClient/Commands/SubCommand.py", line 268, in __init__
    SubCommand.validateOptions(self)
  File "/cvmfs/cms.cern.ch/crab3/slc6_amd64_gcc493/cms/crabclient/3.3.1904/lib/python2.7/site-packages/CRABClient/Commands/SubCommand.py", line 586, in validateOptions
    raise ConfigurationException(msg)
ConfigurationException: [91mError[0m: crab_TTJets-2 is not a valid CRAB project directory.
DEBUG 2019-06-14 23:56:12,781: 	 Executing command: 'status'
DEBUG 2019-06-14 23:56:12,782: 	 Found CRAB cache file /afs/cern.ch/user/q/qihuang/.crab3
ERROR 2019-06-14 23:56:12,783: 	 Error: crab_WJets-1 is not a valid CRAB project directory.
ERROR 2019-06-14 23:56:12,783: 	 Caught exception
Traceback (most recent call last):
  File "/cvmfs/cms.cern.ch/crab3/slc6_amd64_gcc493/cms/crabclient/3.3.1904/bin/crab", line 161, in <module>
    client()
  File "/cvmfs/cms.cern.ch/crab3/slc6_amd64_gcc493/cms/crabclient/3.3.1904/bin/crab", line 146, in __call__
    self.cmd = sub_cmd(self.logger, args[1:])
  File "/cvmfs/cms.cern.ch/crab3/slc6_amd64_gcc493/cms/crabclient/3.3.1904/lib/python2.7/site-packages/CRABClient/Commands/status.py", line 40, in __init__
    SubCommand.__init__(self, logger, cmdargs)
  File "/cvmfs/cms.cern.ch/crab3/slc6_amd64_gcc493/cms/crabclient/3.3.1904/lib/python2.7/site-packages/CRABClient/Commands/SubCommand.py", line 268, in __init__
    SubCommand.validateOptions(self)
  File "/cvmfs/cms.cern.ch/crab3/slc6_amd64_gcc493/cms/crabclient/3.3.1904/lib/python2.7/site-packages/CRABClient/Commands/SubCommand.py", line 586, in validateOptions
    raise ConfigurationException(msg)
ConfigurationException: [91mError[0m: crab_WJets-1 is not a valid CRAB project directory.
DEBUG 2019-06-14 23:56:13,301: 	 Executing command: 'status'
DEBUG 2019-06-14 23:56:13,301: 	 Found CRAB cache file /afs/cern.ch/user/q/qihuang/.crab3
ERROR 2019-06-14 23:56:13,301: 	 Error: crab_WJets-2 is not a valid CRAB project directory.
ERROR 2019-06-14 23:56:13,301: 	 Caught exception
Traceback (most recent call last):
  File "/cvmfs/cms.cern.ch/crab3/slc6_amd64_gcc493/cms/crabclient/3.3.1904/bin/crab", line 161, in <module>
    client()
  File "/cvmfs/cms.cern.ch/crab3/slc6_amd64_gcc493/cms/crabclient/3.3.1904/bin/crab", line 146, in __call__
    self.cmd = sub_cmd(self.logger, args[1:])
  File "/cvmfs/cms.cern.ch/crab3/slc6_amd64_gcc493/cms/crabclient/3.3.1904/lib/python2.7/site-packages/CRABClient/Commands/status.py", line 40, in __init__
    SubCommand.__init__(self, logger, cmdargs)
  File "/cvmfs/cms.cern.ch/crab3/slc6_amd64_gcc493/cms/crabclient/3.3.1904/lib/python2.7/site-packages/CRABClient/Commands/SubCommand.py", line 268, in __init__
    SubCommand.validateOptions(self)
  File "/cvmfs/cms.cern.ch/crab3/slc6_amd64_gcc493/cms/crabclient/3.3.1904/lib/python2.7/site-packages/CRABClient/Commands/SubCommand.py", line 586, in validateOptions
    raise ConfigurationException(msg)
ConfigurationException: [91mError[0m: crab_WJets-2 is not a valid CRAB project directory.
DEBUG 2019-06-15 14:55:41,293: 	 Executing command: 'status'
DEBUG 2019-06-15 14:55:41,293: 	 Found CRAB cache file /afs/cern.ch/user/q/qihuang/.crab3
ERROR 2019-06-15 14:55:41,293: 	 Error: crab_TTJets-1 is not a valid CRAB project directory.
ERROR 2019-06-15 14:55:41,293: 	 Caught exception
Traceback (most recent call last):
  File "/cvmfs/cms.cern.ch/crab3/slc6_amd64_gcc493/cms/crabclient/3.3.1904/bin/crab", line 161, in <module>
    client()
  File "/cvmfs/cms.cern.ch/crab3/slc6_amd64_gcc493/cms/crabclient/3.3.1904/bin/crab", line 146, in __call__
    self.cmd = sub_cmd(self.logger, args[1:])
  File "/cvmfs/cms.cern.ch/crab3/slc6_amd64_gcc493/cms/crabclient/3.3.1904/lib/python2.7/site-packages/CRABClient/Commands/status.py", line 40, in __init__
    SubCommand.__init__(self, logger, cmdargs)
  File "/cvmfs/cms.cern.ch/crab3/slc6_amd64_gcc493/cms/crabclient/3.3.1904/lib/python2.7/site-packages/CRABClient/Commands/SubCommand.py", line 268, in __init__
    SubCommand.validateOptions(self)
  File "/cvmfs/cms.cern.ch/crab3/slc6_amd64_gcc493/cms/crabclient/3.3.1904/lib/python2.7/site-packages/CRABClient/Commands/SubCommand.py", line 586, in validateOptions
    raise ConfigurationException(msg)
ConfigurationException: [91mError[0m: crab_TTJets-1 is not a valid CRAB project directory.
DEBUG 2019-06-15 14:55:41,876: 	 Executing command: 'status'
DEBUG 2019-06-15 14:55:41,877: 	 Found CRAB cache file /afs/cern.ch/user/q/qihuang/.crab3
ERROR 2019-06-15 14:55:41,877: 	 Error: crab_TTJets-2 is not a valid CRAB project directory.
ERROR 2019-06-15 14:55:41,877: 	 Caught exception
Traceback (most recent call last):
  File "/cvmfs/cms.cern.ch/crab3/slc6_amd64_gcc493/cms/crabclient/3.3.1904/bin/crab", line 161, in <module>
    client()
  File "/cvmfs/cms.cern.ch/crab3/slc6_amd64_gcc493/cms/crabclient/3.3.1904/bin/crab", line 146, in __call__
    self.cmd = sub_cmd(self.logger, args[1:])
  File "/cvmfs/cms.cern.ch/crab3/slc6_amd64_gcc493/cms/crabclient/3.3.1904/lib/python2.7/site-packages/CRABClient/Commands/status.py", line 40, in __init__
    SubCommand.__init__(self, logger, cmdargs)
  File "/cvmfs/cms.cern.ch/crab3/slc6_amd64_gcc493/cms/crabclient/3.3.1904/lib/python2.7/site-packages/CRABClient/Commands/SubCommand.py", line 268, in __init__
    SubCommand.validateOptions(self)
  File "/cvmfs/cms.cern.ch/crab3/slc6_amd64_gcc493/cms/crabclient/3.3.1904/lib/python2.7/site-packages/CRABClient/Commands/SubCommand.py", line 586, in validateOptions
    raise ConfigurationException(msg)
ConfigurationException: [91mError[0m: crab_TTJets-2 is not a valid CRAB project directory.
DEBUG 2019-06-15 14:56:26,973: 	 Executing command: 'status'
DEBUG 2019-06-15 14:56:26,973: 	 Found CRAB cache file /afs/cern.ch/user/q/qihuang/.crab3
ERROR 2019-06-15 14:56:26,973: 	 Error: crab_WJets-1 is not a valid CRAB project directory.
ERROR 2019-06-15 14:56:26,973: 	 Caught exception
Traceback (most recent call last):
  File "/cvmfs/cms.cern.ch/crab3/slc6_amd64_gcc493/cms/crabclient/3.3.1904/bin/crab", line 161, in <module>
    client()
  File "/cvmfs/cms.cern.ch/crab3/slc6_amd64_gcc493/cms/crabclient/3.3.1904/bin/crab", line 146, in __call__
    self.cmd = sub_cmd(self.logger, args[1:])
  File "/cvmfs/cms.cern.ch/crab3/slc6_amd64_gcc493/cms/crabclient/3.3.1904/lib/python2.7/site-packages/CRABClient/Commands/status.py", line 40, in __init__
    SubCommand.__init__(self, logger, cmdargs)
  File "/cvmfs/cms.cern.ch/crab3/slc6_amd64_gcc493/cms/crabclient/3.3.1904/lib/python2.7/site-packages/CRABClient/Commands/SubCommand.py", line 268, in __init__
    SubCommand.validateOptions(self)
  File "/cvmfs/cms.cern.ch/crab3/slc6_amd64_gcc493/cms/crabclient/3.3.1904/lib/python2.7/site-packages/CRABClient/Commands/SubCommand.py", line 586, in validateOptions
    raise ConfigurationException(msg)
ConfigurationException: [91mError[0m: crab_WJets-1 is not a valid CRAB project directory.
DEBUG 2019-06-15 14:56:27,478: 	 Executing command: 'status'
DEBUG 2019-06-15 14:56:27,478: 	 Found CRAB cache file /afs/cern.ch/user/q/qihuang/.crab3
ERROR 2019-06-15 14:56:27,478: 	 Error: crab_WJets-2 is not a valid CRAB project directory.
ERROR 2019-06-15 14:56:27,478: 	 Caught exception
Traceback (most recent call last):
  File "/cvmfs/cms.cern.ch/crab3/slc6_amd64_gcc493/cms/crabclient/3.3.1904/bin/crab", line 161, in <module>
    client()
  File "/cvmfs/cms.cern.ch/crab3/slc6_amd64_gcc493/cms/crabclient/3.3.1904/bin/crab", line 146, in __call__
    self.cmd = sub_cmd(self.logger, args[1:])
  File "/cvmfs/cms.cern.ch/crab3/slc6_amd64_gcc493/cms/crabclient/3.3.1904/lib/python2.7/site-packages/CRABClient/Commands/status.py", line 40, in __init__
    SubCommand.__init__(self, logger, cmdargs)
  File "/cvmfs/cms.cern.ch/crab3/slc6_amd64_gcc493/cms/crabclient/3.3.1904/lib/python2.7/site-packages/CRABClient/Commands/SubCommand.py", line 268, in __init__
    SubCommand.validateOptions(self)
  File "/cvmfs/cms.cern.ch/crab3/slc6_amd64_gcc493/cms/crabclient/3.3.1904/lib/python2.7/site-packages/CRABClient/Commands/SubCommand.py", line 586, in validateOptions
    raise ConfigurationException(msg)
ConfigurationException: [91mError[0m: crab_WJets-2 is not a valid CRAB project directory.
DEBUG 2019-06-16 10:00:46,868: 	 Executing command: 'status'
DEBUG 2019-06-16 10:00:46,869: 	 Found CRAB cache file /afs/cern.ch/user/q/qihuang/.crab3
ERROR 2019-06-16 10:00:46,871: 	 Error: crab_TTJets-1 is not a valid CRAB project directory.
ERROR 2019-06-16 10:00:46,871: 	 Caught exception
Traceback (most recent call last):
  File "/cvmfs/cms.cern.ch/crab3/slc6_amd64_gcc493/cms/crabclient/3.3.1904/bin/crab", line 161, in <module>
    client()
  File "/cvmfs/cms.cern.ch/crab3/slc6_amd64_gcc493/cms/crabclient/3.3.1904/bin/crab", line 146, in __call__
    self.cmd = sub_cmd(self.logger, args[1:])
  File "/cvmfs/cms.cern.ch/crab3/slc6_amd64_gcc493/cms/crabclient/3.3.1904/lib/python2.7/site-packages/CRABClient/Commands/status.py", line 40, in __init__
    SubCommand.__init__(self, logger, cmdargs)
  File "/cvmfs/cms.cern.ch/crab3/slc6_amd64_gcc493/cms/crabclient/3.3.1904/lib/python2.7/site-packages/CRABClient/Commands/SubCommand.py", line 268, in __init__
    SubCommand.validateOptions(self)
  File "/cvmfs/cms.cern.ch/crab3/slc6_amd64_gcc493/cms/crabclient/3.3.1904/lib/python2.7/site-packages/CRABClient/Commands/SubCommand.py", line 586, in validateOptions
    raise ConfigurationException(msg)
ConfigurationException: [91mError[0m: crab_TTJets-1 is not a valid CRAB project directory.
DEBUG 2019-06-16 10:00:47,414: 	 Executing command: 'status'
DEBUG 2019-06-16 10:00:47,415: 	 Found CRAB cache file /afs/cern.ch/user/q/qihuang/.crab3
ERROR 2019-06-16 10:00:47,415: 	 Error: crab_TTJets-2 is not a valid CRAB project directory.
ERROR 2019-06-16 10:00:47,415: 	 Caught exception
Traceback (most recent call last):
  File "/cvmfs/cms.cern.ch/crab3/slc6_amd64_gcc493/cms/crabclient/3.3.1904/bin/crab", line 161, in <module>
    client()
  File "/cvmfs/cms.cern.ch/crab3/slc6_amd64_gcc493/cms/crabclient/3.3.1904/bin/crab", line 146, in __call__
    self.cmd = sub_cmd(self.logger, args[1:])
  File "/cvmfs/cms.cern.ch/crab3/slc6_amd64_gcc493/cms/crabclient/3.3.1904/lib/python2.7/site-packages/CRABClient/Commands/status.py", line 40, in __init__
    SubCommand.__init__(self, logger, cmdargs)
  File "/cvmfs/cms.cern.ch/crab3/slc6_amd64_gcc493/cms/crabclient/3.3.1904/lib/python2.7/site-packages/CRABClient/Commands/SubCommand.py", line 268, in __init__
    SubCommand.validateOptions(self)
  File "/cvmfs/cms.cern.ch/crab3/slc6_amd64_gcc493/cms/crabclient/3.3.1904/lib/python2.7/site-packages/CRABClient/Commands/SubCommand.py", line 586, in validateOptions
    raise ConfigurationException(msg)
ConfigurationException: [91mError[0m: crab_TTJets-2 is not a valid CRAB project directory.
DEBUG 2019-06-16 10:01:40,213: 	 Executing command: 'status'
DEBUG 2019-06-16 10:01:40,213: 	 Found CRAB cache file /afs/cern.ch/user/q/qihuang/.crab3
ERROR 2019-06-16 10:01:40,214: 	 Error: crab_WJets-1 is not a valid CRAB project directory.
ERROR 2019-06-16 10:01:40,214: 	 Caught exception
Traceback (most recent call last):
  File "/cvmfs/cms.cern.ch/crab3/slc6_amd64_gcc493/cms/crabclient/3.3.1904/bin/crab", line 161, in <module>
    client()
  File "/cvmfs/cms.cern.ch/crab3/slc6_amd64_gcc493/cms/crabclient/3.3.1904/bin/crab", line 146, in __call__
    self.cmd = sub_cmd(self.logger, args[1:])
  File "/cvmfs/cms.cern.ch/crab3/slc6_amd64_gcc493/cms/crabclient/3.3.1904/lib/python2.7/site-packages/CRABClient/Commands/status.py", line 40, in __init__
    SubCommand.__init__(self, logger, cmdargs)
  File "/cvmfs/cms.cern.ch/crab3/slc6_amd64_gcc493/cms/crabclient/3.3.1904/lib/python2.7/site-packages/CRABClient/Commands/SubCommand.py", line 268, in __init__
    SubCommand.validateOptions(self)
  File "/cvmfs/cms.cern.ch/crab3/slc6_amd64_gcc493/cms/crabclient/3.3.1904/lib/python2.7/site-packages/CRABClient/Commands/SubCommand.py", line 586, in validateOptions
    raise ConfigurationException(msg)
ConfigurationException: [91mError[0m: crab_WJets-1 is not a valid CRAB project directory.
DEBUG 2019-06-16 10:01:40,712: 	 Executing command: 'status'
DEBUG 2019-06-16 10:01:40,712: 	 Found CRAB cache file /afs/cern.ch/user/q/qihuang/.crab3
ERROR 2019-06-16 10:01:40,713: 	 Error: crab_WJets-2 is not a valid CRAB project directory.
ERROR 2019-06-16 10:01:40,713: 	 Caught exception
Traceback (most recent call last):
  File "/cvmfs/cms.cern.ch/crab3/slc6_amd64_gcc493/cms/crabclient/3.3.1904/bin/crab", line 161, in <module>
    client()
  File "/cvmfs/cms.cern.ch/crab3/slc6_amd64_gcc493/cms/crabclient/3.3.1904/bin/crab", line 146, in __call__
    self.cmd = sub_cmd(self.logger, args[1:])
  File "/cvmfs/cms.cern.ch/crab3/slc6_amd64_gcc493/cms/crabclient/3.3.1904/lib/python2.7/site-packages/CRABClient/Commands/status.py", line 40, in __init__
    SubCommand.__init__(self, logger, cmdargs)
  File "/cvmfs/cms.cern.ch/crab3/slc6_amd64_gcc493/cms/crabclient/3.3.1904/lib/python2.7/site-packages/CRABClient/Commands/SubCommand.py", line 268, in __init__
    SubCommand.validateOptions(self)
  File "/cvmfs/cms.cern.ch/crab3/slc6_amd64_gcc493/cms/crabclient/3.3.1904/lib/python2.7/site-packages/CRABClient/Commands/SubCommand.py", line 586, in validateOptions
    raise ConfigurationException(msg)
ConfigurationException: [91mError[0m: crab_WJets-2 is not a valid CRAB project directory.
DEBUG 2019-06-16 17:34:46,975: 	 Executing command: 'submit'
DEBUG 2019-06-16 17:34:46,976: 	 Found CRAB cache file /afs/cern.ch/user/q/qihuang/.crab3
DEBUG 2019-06-16 17:34:47,025: 	 Checking credentials
DEBUG 2019-06-16 17:34:47,028: 	 Proxy file /tmp/x509up_u91611 not found
DEBUG 2019-06-16 17:34:47,028: 	 Creating new proxy for 24:00 hours with VO group '' and VO role 'NULL'.
ERROR 2019-06-16 17:34:54,999: 	 Keyboard Interrupted
DEBUG 2019-06-16 17:35:04,331: 	 Executing command: 'submit'
DEBUG 2019-06-16 17:35:04,333: 	 Found CRAB cache file /afs/cern.ch/user/q/qihuang/.crab3
DEBUG 2019-06-16 17:35:04,347: 	 Checking credentials
DEBUG 2019-06-16 17:35:04,347: 	 Proxy file /tmp/x509up_u91611 not found
DEBUG 2019-06-16 17:35:04,347: 	 Creating new proxy for 24:00 hours with VO group '' and VO role 'NULL'.
DEBUG 2019-06-16 17:35:12,167: 	 Executing : 
 command : voms-proxy-init -voms cms:/cms -valid 24:00 -rfc
 output : None
 error: None
 retcode : 1
DEBUG 2019-06-16 17:35:12,779: 	 Executing : 
 command : voms-proxy-info -file /tmp/x509up_u91611 -timeleft
 output : 
 error: Proxy not found: /tmp/x509up_u91611 (No such file or directory)

 retcode : 1
ERROR 2019-06-16 17:35:12,780: 	 Error while checking proxy timeleft for /tmp/x509up_u91611
DEBUG 2019-06-16 17:35:13,587: 	 Executing : 
 command : env X509_USER_PROXY=/tmp/x509up_u91611 voms-proxy-info -fqan
 output : 
 error: Proxy not found: /tmp/x509up_u91611 (No such file or directory)

 retcode : 1
ERROR 2019-06-16 17:35:13,587: 	 Problems creating proxy.
ERROR 2019-06-16 17:35:13,587: 	 Caught exception
Traceback (most recent call last):
  File "/cvmfs/cms.cern.ch/crab3/slc6_amd64_gcc493/cms/crabclient/3.3.1904/bin/crab", line 161, in <module>
    client()
  File "/cvmfs/cms.cern.ch/crab3/slc6_amd64_gcc493/cms/crabclient/3.3.1904/bin/crab", line 146, in __call__
    self.cmd = sub_cmd(self.logger, args[1:])
  File "/cvmfs/cms.cern.ch/crab3/slc6_amd64_gcc493/cms/crabclient/3.3.1904/lib/python2.7/site-packages/CRABClient/Commands/submit.py", line 34, in __init__
    SubCommand.__init__(self, logger, cmdargs, disable_interspersed_args=True)
  File "/cvmfs/cms.cern.ch/crab3/slc6_amd64_gcc493/cms/crabclient/3.3.1904/lib/python2.7/site-packages/CRABClient/Commands/SubCommand.py", line 305, in __init__
    self.proxyCreated = self.proxy.createNewVomsProxySimple(timeLeftThreshold = 720)
  File "/cvmfs/cms.cern.ch/crab3/slc6_amd64_gcc493/cms/crabclient/3.3.1904/lib/python2.7/site-packages/CRABClient/CredentialInteractions.py", line 126, in createNewVomsProxySimple
    raise ProxyCreationException("Problems creating proxy.")
ProxyCreationException: Problems creating proxy.
DEBUG 2019-06-16 17:35:16,587: 	 Executing command: 'submit'
DEBUG 2019-06-16 17:35:16,587: 	 Found CRAB cache file /afs/cern.ch/user/q/qihuang/.crab3
DEBUG 2019-06-16 17:35:16,596: 	 Checking credentials
DEBUG 2019-06-16 17:35:16,599: 	 Proxy file /tmp/x509up_u91611 not found
DEBUG 2019-06-16 17:35:16,599: 	 Creating new proxy for 24:00 hours with VO group '' and VO role 'NULL'.
DEBUG 2019-06-16 17:35:21,117: 	 Executing : 
 command : voms-proxy-init -voms cms:/cms -valid 24:00 -rfc
 output : None
 error: None
 retcode : 1
DEBUG 2019-06-16 17:35:21,722: 	 Executing : 
 command : voms-proxy-info -file /tmp/x509up_u91611 -timeleft
 output : 
 error: Proxy not found: /tmp/x509up_u91611 (No such file or directory)

 retcode : 1
ERROR 2019-06-16 17:35:21,723: 	 Error while checking proxy timeleft for /tmp/x509up_u91611
DEBUG 2019-06-16 17:35:22,328: 	 Executing : 
 command : env X509_USER_PROXY=/tmp/x509up_u91611 voms-proxy-info -fqan
 output : 
 error: Proxy not found: /tmp/x509up_u91611 (No such file or directory)

 retcode : 1
ERROR 2019-06-16 17:35:22,329: 	 Problems creating proxy.
ERROR 2019-06-16 17:35:22,329: 	 Caught exception
Traceback (most recent call last):
  File "/cvmfs/cms.cern.ch/crab3/slc6_amd64_gcc493/cms/crabclient/3.3.1904/bin/crab", line 161, in <module>
    client()
  File "/cvmfs/cms.cern.ch/crab3/slc6_amd64_gcc493/cms/crabclient/3.3.1904/bin/crab", line 146, in __call__
    self.cmd = sub_cmd(self.logger, args[1:])
  File "/cvmfs/cms.cern.ch/crab3/slc6_amd64_gcc493/cms/crabclient/3.3.1904/lib/python2.7/site-packages/CRABClient/Commands/submit.py", line 34, in __init__
    SubCommand.__init__(self, logger, cmdargs, disable_interspersed_args=True)
  File "/cvmfs/cms.cern.ch/crab3/slc6_amd64_gcc493/cms/crabclient/3.3.1904/lib/python2.7/site-packages/CRABClient/Commands/SubCommand.py", line 305, in __init__
    self.proxyCreated = self.proxy.createNewVomsProxySimple(timeLeftThreshold = 720)
  File "/cvmfs/cms.cern.ch/crab3/slc6_amd64_gcc493/cms/crabclient/3.3.1904/lib/python2.7/site-packages/CRABClient/CredentialInteractions.py", line 126, in createNewVomsProxySimple
    raise ProxyCreationException("Problems creating proxy.")
ProxyCreationException: Problems creating proxy.
DEBUG 2019-06-16 17:35:30,944: 	 Executing command: 'submit'
DEBUG 2019-06-16 17:35:30,944: 	 Found CRAB cache file /afs/cern.ch/user/q/qihuang/.crab3
DEBUG 2019-06-16 17:35:30,954: 	 Checking credentials
DEBUG 2019-06-16 17:35:30,954: 	 Proxy file /tmp/x509up_u91611 not found
DEBUG 2019-06-16 17:35:30,955: 	 Creating new proxy for 24:00 hours with VO group '' and VO role 'NULL'.
DEBUG 2019-06-16 17:35:37,079: 	 Executing : 
 command : voms-proxy-init -voms cms:/cms -valid 24:00 -rfc
 output : None
 error: None
 retcode : 1
DEBUG 2019-06-16 17:35:37,687: 	 Executing : 
 command : voms-proxy-info -file /tmp/x509up_u91611 -timeleft
 output : 
 error: Proxy not found: /tmp/x509up_u91611 (No such file or directory)

 retcode : 1
ERROR 2019-06-16 17:35:37,688: 	 Error while checking proxy timeleft for /tmp/x509up_u91611
DEBUG 2019-06-16 17:35:38,294: 	 Executing : 
 command : env X509_USER_PROXY=/tmp/x509up_u91611 voms-proxy-info -fqan
 output : 
 error: Proxy not found: /tmp/x509up_u91611 (No such file or directory)

 retcode : 1
ERROR 2019-06-16 17:35:38,294: 	 Problems creating proxy.
ERROR 2019-06-16 17:35:38,295: 	 Caught exception
Traceback (most recent call last):
  File "/cvmfs/cms.cern.ch/crab3/slc6_amd64_gcc493/cms/crabclient/3.3.1904/bin/crab", line 161, in <module>
    client()
  File "/cvmfs/cms.cern.ch/crab3/slc6_amd64_gcc493/cms/crabclient/3.3.1904/bin/crab", line 146, in __call__
    self.cmd = sub_cmd(self.logger, args[1:])
  File "/cvmfs/cms.cern.ch/crab3/slc6_amd64_gcc493/cms/crabclient/3.3.1904/lib/python2.7/site-packages/CRABClient/Commands/submit.py", line 34, in __init__
    SubCommand.__init__(self, logger, cmdargs, disable_interspersed_args=True)
  File "/cvmfs/cms.cern.ch/crab3/slc6_amd64_gcc493/cms/crabclient/3.3.1904/lib/python2.7/site-packages/CRABClient/Commands/SubCommand.py", line 305, in __init__
    self.proxyCreated = self.proxy.createNewVomsProxySimple(timeLeftThreshold = 720)
  File "/cvmfs/cms.cern.ch/crab3/slc6_amd64_gcc493/cms/crabclient/3.3.1904/lib/python2.7/site-packages/CRABClient/CredentialInteractions.py", line 126, in createNewVomsProxySimple
    raise ProxyCreationException("Problems creating proxy.")
ProxyCreationException: Problems creating proxy.
DEBUG 2019-06-16 17:35:54,876: 	 Executing command: 'submit'
DEBUG 2019-06-16 17:35:54,876: 	 Found CRAB cache file /afs/cern.ch/user/q/qihuang/.crab3
DEBUG 2019-06-16 17:35:54,888: 	 Checking credentials
DEBUG 2019-06-16 17:35:54,890: 	 Proxy file /tmp/x509up_u91611 not found
DEBUG 2019-06-16 17:35:54,890: 	 Creating new proxy for 24:00 hours with VO group '' and VO role 'NULL'.
DEBUG 2019-06-16 17:35:58,402: 	 Executing : 
 command : voms-proxy-init -voms cms:/cms -valid 24:00 -rfc
 output : None
 error: None
 retcode : 1
DEBUG 2019-06-16 17:35:59,011: 	 Executing : 
 command : voms-proxy-info -file /tmp/x509up_u91611 -timeleft
 output : 
 error: Proxy not found: /tmp/x509up_u91611 (No such file or directory)

 retcode : 1
ERROR 2019-06-16 17:35:59,011: 	 Error while checking proxy timeleft for /tmp/x509up_u91611
DEBUG 2019-06-16 17:35:59,621: 	 Executing : 
 command : env X509_USER_PROXY=/tmp/x509up_u91611 voms-proxy-info -fqan
 output : 
 error: Proxy not found: /tmp/x509up_u91611 (No such file or directory)

 retcode : 1
ERROR 2019-06-16 17:35:59,621: 	 Problems creating proxy.
ERROR 2019-06-16 17:35:59,622: 	 Caught exception
Traceback (most recent call last):
  File "/cvmfs/cms.cern.ch/crab3/slc6_amd64_gcc493/cms/crabclient/3.3.1904/bin/crab", line 161, in <module>
    client()
  File "/cvmfs/cms.cern.ch/crab3/slc6_amd64_gcc493/cms/crabclient/3.3.1904/bin/crab", line 146, in __call__
    self.cmd = sub_cmd(self.logger, args[1:])
  File "/cvmfs/cms.cern.ch/crab3/slc6_amd64_gcc493/cms/crabclient/3.3.1904/lib/python2.7/site-packages/CRABClient/Commands/submit.py", line 34, in __init__
    SubCommand.__init__(self, logger, cmdargs, disable_interspersed_args=True)
  File "/cvmfs/cms.cern.ch/crab3/slc6_amd64_gcc493/cms/crabclient/3.3.1904/lib/python2.7/site-packages/CRABClient/Commands/SubCommand.py", line 305, in __init__
    self.proxyCreated = self.proxy.createNewVomsProxySimple(timeLeftThreshold = 720)
  File "/cvmfs/cms.cern.ch/crab3/slc6_amd64_gcc493/cms/crabclient/3.3.1904/lib/python2.7/site-packages/CRABClient/CredentialInteractions.py", line 126, in createNewVomsProxySimple
    raise ProxyCreationException("Problems creating proxy.")
ProxyCreationException: Problems creating proxy.
DEBUG 2019-09-27 15:32:40.016 UTC: 	 Executing command: 'submit'
DEBUG 2019-09-27 15:32:40.017 UTC: 	 Found CRAB cache file /afs/cern.ch/user/q/qihuang/.crab3
DEBUG 2019-09-27 15:32:40.038 UTC: 	 Checking credentials
DEBUG 2019-09-27 15:32:40.038 UTC: 	 Proxy file /tmp/x509up_u91611 not found
DEBUG 2019-09-27 15:32:40.038 UTC: 	 Creating new proxy for 24:00 hours with VO group '' and VO role 'NULL'.
DEBUG 2019-09-27 15:32:48.777 UTC: 	 Executing : 
 command : voms-proxy-init -voms cms:/cms -valid 24:00 -rfc
 output : None
 error: None
 retcode : 1
DEBUG 2019-09-27 15:32:49.386 UTC: 	 Executing : 
 command : voms-proxy-info -file /tmp/x509up_u91611 -timeleft
 output : 
 error: Proxy not found: /tmp/x509up_u91611 (No such file or directory)

 retcode : 1
ERROR 2019-09-27 15:32:49.386 UTC: 	 Error while checking proxy timeleft for /tmp/x509up_u91611
DEBUG 2019-09-27 15:32:49.992 UTC: 	 Executing : 
 command : env X509_USER_PROXY=/tmp/x509up_u91611 voms-proxy-info -fqan
 output : 
 error: Proxy not found: /tmp/x509up_u91611 (No such file or directory)

 retcode : 1
ERROR 2019-09-27 15:32:49.992 UTC: 	 Problems creating proxy.
ERROR 2019-09-27 15:32:49.992 UTC: 	 Caught exception
Traceback (most recent call last):
  File "/cvmfs/cms.cern.ch/crab3/slc6_amd64_gcc493/cms/crabclient/3.3.1909/bin/crab", line 160, in <module>
    client()
  File "/cvmfs/cms.cern.ch/crab3/slc6_amd64_gcc493/cms/crabclient/3.3.1909/bin/crab", line 145, in __call__
    self.cmd = sub_cmd(self.logger, args[1:])
  File "/cvmfs/cms.cern.ch/crab3/slc6_amd64_gcc493/cms/crabclient/3.3.1909/lib/python2.7/site-packages/CRABClient/Commands/submit.py", line 34, in __init__
    SubCommand.__init__(self, logger, cmdargs, disable_interspersed_args=True)
  File "/cvmfs/cms.cern.ch/crab3/slc6_amd64_gcc493/cms/crabclient/3.3.1909/lib/python2.7/site-packages/CRABClient/Commands/SubCommand.py", line 305, in __init__
    self.proxyCreated = self.proxy.createNewVomsProxySimple(timeLeftThreshold = 720)
  File "/cvmfs/cms.cern.ch/crab3/slc6_amd64_gcc493/cms/crabclient/3.3.1909/lib/python2.7/site-packages/CRABClient/CredentialInteractions.py", line 126, in createNewVomsProxySimple
    raise ProxyCreationException("Problems creating proxy.")
ProxyCreationException: Problems creating proxy.
